Workbook
Name Индексы: Содержание!$B$3

Sheet Содержание
A1: Содержание:
A3: 1. | B3: Индексы физического объема валового регионального продукта и валовой добавленной стоимости по отраслям экономики субъектов Российской Федерации 2017-2024 гг.:
B4: 2017 год | C4: 2018 год | D4: 2019 год | E4: 2020 год | F4: 2021 год | G4: 2022 год | I4: 2023 год | K4: 2024 год
A6: 2. | B6: Валовая добавленная стоимость по отралям экономики субъектов Российской Федерации за 2016-2024 гг.:
B7: 2016 год | C7: 2017 год | D7: 2018 год | E7: 2019 год | F7: 2020 год | G7: 2021 год | I7: 2022 год | K7: 2023 год | L7: 2024 год
A9: 3. | B9: Отраслевая структура валовой добавленной стоимости субъектов Российской Федерации 2016-2024 гг.:
B10: 2016 год | C10: 2017 год | D10: 2018 год | E10: 2019 год | F10: 2020 год | G10: 2021 год | I10: 2022 год | K10: 2023 год | L10: 2024 год
A12: 4. | B12: Валовой региональный продукт (в постоянных ценах 2016 года) и валовая добавленная стоимость по отралям экономики (в постоянных ценах 2016 года) субъектов Российской Федерации за 2016-2022 гг.:
B13: 2016 год | C13: 2017 год | D13: 2018 год | E13: 2019 год | F13: 2020 год | G13: 2021 год | I13: 2022 год
A15: 5. | B15: Валовой региональный продукт (в постоянных ценах 2021 года) и валовая добавленная стоимость по отралям экономики (в постоянных ценах 2021 года) субъектов Российской Федерации за 2021-2024 гг.:
B16: 2021 год | C16: 2022 год | D16: 2023 год | E16: 2024 год
A18: 6. | B18: Справочная информация о последующих публикациях
B19: Ответственный исполнитель:
B20: Баранов Александр Олегович
B21: 8 (495) 568-00-42 (доб. 99-927)
B24: Обновлено: 05.03.2026 г.

Sheet 1. 2017
A1: К содержанию
A2: Индексы физического объема валового регионального продукта и валовой добавленной стоимости по отраслям экономики в 2017 году1)2) (в процентах к предыдущему году)
B3: Валовой региональный продукт (валовая добавленная стоимость в основных ценах) | C3: Раздел A | D3: Раздел B | E3: Раздел C | F3: Раздел D | G3: Раздел E | H3: Раздел F | I3: Раздел G | J3: Раздел H | K3: Раздел I | L3: Раздел J | M3: Раздел K | N3: Раздел L | Q3: Раздел M | R3: Раздел N | S3: Раздел О | T3: Раздел P | U3: Раздел Q | V3: Раздел R | W3: Раздел S | X3: Раздел T
N4: Деятельность по операциям с недвижимым имуществом | O4: в том числе:
C5: Сельское, лесное хозяйство, охота, рыболовство и рыбоводство | D5: Добыча полезных ископаемых | E5: Обрабатывающие производства | F5: Обеспечение электрической энергией, газом и паром; кондиционирование воздуха | G5: Водоснабжение; водоотведение, организация сбора и утилизация отходов, деятельность по ликвидации загрязнений | H5: Строительство | I5: Торговля оптовая и розничная; ремонт автотранспортных средств и мотоциклов | J5: Транспортировка и хранение | K5: Деятельность гостиниц и предприятий общественного питания | L5: Деятельность в области информации и связи | M5: Деятельность финансовая и страховая | O5: Операции с недвижимым имуществом | P5: Услуги по проживанию в собственном жилище | Q5: Деятельность профессиональная, научная и техническая | R5: Деятельность административная и сопутствующие дополнительные услуги | S5: Государственное управление и обеспечение военной безопасности; социальное обеспечение | T5: Образование | U5: Деятельность в области здравоохранения и социальных услуг | V5: Деятельность в области культуры, спорта, организации досуга и развлечений | W5: Предоставление прочих видов услуг | X5: Деятельность домашних хозяйств как работодателей; недифференцированная деятельность частных домашних хозяйств по производству1)
A6: Российская Федерация из суммы субъектов | B6: 101.9 | C6: 102.20436 | D6: 102.20989 | E6: 103.06041 | F6: 96.363068 | G6: 102.27433 | H6: 96.965408 | I6: 103.3423 | J6: 101.0318 | K6: 100.69358 | L6: 102.07225 | M6: 94.481346 | N6: 105.5163 | O6: 107.38311 | P6: 104.34818 | Q6: 98.231077 | R6: 103.22848 | S6: 100.50452 | T6: 101.68233 | U6: 99.144439 | V6: 109.46895 | W6: 102.88452 | X6: 0
A7: Центральный федеральный округ | B7: 101.9 | C7: 105.11749 | D7: 111.31483 | E7: 102.37838 | F7: 88.150146 | G7: 100.73946 | H7: 90.660211 | I7: 106.62444 | J7: 99.280018 | K7: 93.200148 | L7: 101.22923 | M7: 94.420115 | N7: 106.31075 | O7: 109.77534 | P7: 103.56629 | Q7: 93.912839 | R7: 105.89181 | S7: 100.17905 | T7: 102.01638 | U7: 99.177581 | V7: 124.46465 | W7: 94.1502 | X7: 0
A8: Белгородская область | B8: 104 | C8: 101.7 | D8: 113.5 | E8: 104.2 | F8: 100.5 | G8: 97 | H8: 90.1 | I8: 101.4 | J8: 105.6 | K8: 103.8 | L8: 112.5 | M8: 76.9 | N8: 109.8 | O8: 118.45426 | P8: 106.24107 | Q8: 109.2 | R8: 106.8 | S8: 108.2 | T8: 102 | U8: 99.3 | V8: 106.6 | W8: 106.6 | X8: 0
A9: Брянская область | B9: 104 | C9: 115.2 | D9: 137.6 | E9: 106.9 | F9: 102.8 | G9: 112.4 | H9: 84.6 | I9: 105.1 | J9: 102.7 | K9: 103.1 | L9: 105.1 | M9: 106 | N9: 99 | O9: 99.219064 | P9: 98.918799 | Q9: 105.6 | R9: 82.8 | S9: 98 | T9: 101.8 | U9: 100.4 | V9: 116.6 | W9: 92 | X9: 0
A10: Владимирская область | B10: 100.7 | C10: 104.6 | D10: 129.3 | E10: 96 | F10: 65.3 | G10: 107.7 | H10: 103.5 | I10: 120.9 | J10: 103.9 | K10: 94.7 | L10: 117.2 | M10: 97.5 | N10: 99.4 | O10: 92.88477 | P10: 103.24142 | Q10: 109.5 | R10: 95.2 | S10: 94.9 | T10: 104.9 | U10: 98.8 | V10: 103.2 | W10: 117.5 | X10: 0
A11: Воронежская область | B11: 102.4 | C11: 108.2 | D11: 128.6 | E11: 96.2 | F11: 81.3 | G11: 114.6 | H11: 104.1 | I11: 107.1 | J11: 98.8 | K11: 103.5 | L11: 126.8 | M11: 96.7 | N11: 101.8 | O11: 101.79626 | P11: 101.80744 | Q11: 100 | R11: 98.2 | S11: 101.6 | T11: 99.2 | U11: 100.4 | V11: 98.2 | W11: 108 | X11: 0
A12: Ивановская область | B12: 99.5 | C12: 74.9 | D12: 50.5 | E12: 108.4 | F12: 99.9 | G12: 112.1 | H12: 96.4 | I12: 88.9 | J12: 146.6 | K12: 103.2 | L12: 98.1 | M12: 159.6 | N12: 98.3 | O12: 96.961714 | P12: 99.024026 | Q12: 84.9 | R12: 88.8 | S12: 97.8 | T12: 98.7 | U12: 99.4 | V12: 90.5 | W12: 168.7 | X12: 0
A13: Калужская область | B13: 105.4 | C13: 111.9 | D13: 106.3 | E13: 114.8 | F13: 97.9 | G13: 114.8 | H13: 85.2 | I13: 99.4 | J13: 97.4 | K13: 121.5 | L13: 77.9 | M13: 113 | N13: 106.8 | O13: 116.976 | P13: 102.65325 | Q13: 103.2 | R13: 127.9 | S13: 100.3 | T13: 98.8 | U13: 98.9 | V13: 93.2 | W13: 97.7 | X13: 0
A14: Костромская область | B14: 102.3 | C14: 104.5 | D14: 60 | E14: 107.3 | F14: 103.5 | G14: 107.7 | H14: 89.2 | I14: 97.3 | J14: 98.9 | K14: 100.6 | L14: 100.7 | M14: 85.5 | N14: 103.8 | O14: 100.88382 | P14: 105.4071 | Q14: 109 | R14: 120.9 | S14: 104.8 | T14: 99.9 | U14: 100.1 | V14: 97.7 | W14: 104 | X14: 0
A15: Курская область | B15: 102.8 | C15: 107.9 | D15: 101.2 | E15: 105.9 | F15: 104.1 | G15: 112.2 | H15: 82.8 | I15: 103.5 | J15: 106.9 | K15: 124.4 | L15: 90.3 | M15: 83.4 | N15: 105.9 | O15: 99.620167 | P15: 109.24691 | Q15: 90 | R15: 102.9 | S15: 99.4 | T15: 102.6 | U15: 101.5 | V15: 100.4 | W15: 105.1 | X15: 0
A16: Липецкая область | B16: 101.1 | C16: 103.5 | D16: 91.2 | E16: 98.1 | F16: 112.7 | G16: 64.3 | H16: 90.6 | I16: 100.5 | J16: 128.8 | K16: 99.8 | L16: 108.3 | M16: 85.6 | N16: 113 | O16: 141.24917 | P16: 103.8493 | Q16: 103.7 | R16: 99.1 | S16: 100 | T16: 100.3 | U16: 97.2 | V16: 93.9 | W16: 106.1 | X16: 0
A17: Московская область | B17: 101.9 | C17: 92.2 | D17: 124 | E17: 110.1 | F17: 83.6 | G17: 116.6 | H17: 75.2 | I17: 102.7 | J17: 97.3 | K17: 83 | L17: 112.9 | M17: 79.8 | N17: 100.9 | O17: 94.307996 | P17: 105.31466 | Q17: 103.6 | R17: 158.5 | S17: 103.7 | T17: 104.5 | U17: 95.3 | V17: 121.5 | W17: 90.3 | X17: 0
... A101: Чукотский автономный округ | B101: 100.1 | C101: 270 | D101: 86.9 | E101: 102.8 | F101: 123.8 | G101: 96 | H101: 82.2 | I101: 120.6 | J101: 138.9 | K101: 144.4 | L101: 64.2 | M101: 391.7 | N101: 140.4 | O101: 179.83161 | P101: 129.7499 | Q101: 74.8 | R101: 156.9 | S101: 102.4 | T101: 101 | U101: 96.5 | V101: 101.1 | W101: 130.5 | X101: 0
A103: 1) Данные динамического ряда, начиная с 2016 года, содержат изменения, связанные с внедрением международной методологии оценки жилищных услуг, производимых и потребляемых собственниками жилья; оценкой потребления основного капитала, исходя из его текущей рыночной стоимости.
A104: 2)Данные динамического ряда, начиная с 2017 года, содержат изменения, связанные с включением в формирование показателей деятельности: кредитных организаций; финансовых услуг, кроме услуг по страхованию и пенсионному обеспечению; негосударственных пенсионных фондов; вспомогательной в сфере финансовых услуг и страхования.

Sheet 1. 2018
A1: К содержанию
A2: Индексы физического объема валового регионального продукта и валовой добавленной стоимости по отраслям экономики в 2018 году1)2) (в процентах к предыдущему году)
B3: Валовой региональный продукт (валовая добавленная стоимость в основных ценах) | C3: Раздел A | D3: Раздел B | E3: Раздел C | F3: Раздел D | G3: Раздел E | H3: Раздел F | I3: Раздел G | J3: Раздел H | K3: Раздел I | L3: Раздел J | M3: Раздел K | N3: Раздел L | Q3: Раздел M | R3: Раздел N | S3: Раздел О | T3: Раздел P | U3: Раздел Q | V3: Раздел R | W3: Раздел S | X3: Раздел T
N4: Деятельность по операциям с недвижимым имуществом | O4: в том числе:
C5: Сельское, лесное хозяйство, охота, рыболовство и рыбоводство | D5: Добыча полезных ископаемых | E5: Обрабатывающие производства | F5: Обеспечение электрической энергией, газом и паром; кондиционирование воздуха | G5: Водоснабжение; водоотведение, организация сбора и утилизация отходов, деятельность по ликвидации загрязнений | H5: Строительство | I5: Торговля оптовая и розничная; ремонт автотранспортных средств и мотоциклов | J5: Транспортировка и хранение | K5: Деятельность гостиниц и предприятий общественного питания | L5: Деятельность в области информации и связи | M5: Деятельность финансовая и страховая | O5: Операции с недвижимым имуществом | P5: Услуги по проживанию в собственном жилище | Q5: Деятельность профессиональная, научная и техническая | R5: Деятельность административная и сопутствующие дополнительные услуги | S5: Государственное управление и обеспечение военной безопасности; социальное обеспечение | T5: Образование | U5: Деятельность в области здравоохранения и социальных услуг | V5: Деятельность в области культуры, спорта, организации досуга и развлечений | W5: Предоставление прочих видов услуг | X5: Деятельность домашних хозяйств как работодателей; недифференцированная деятельность частных домашних хозяйств по производству1)
A6: Российская Федерация из суммы субъектов | B6: 103 | C6: 102.02481 | D6: 105.99932 | E6: 103.63234 | F6: 99.638618 | G6: 103.18964 | H6: 99.632613 | I6: 101.43922 | J6: 101.7648 | K6: 107.33797 | L6: 107.84628 | M6: 109.24845 | N6: 103.56243 | O6: 104.55762 | P6: 102.88484 | Q6: 101.29126 | R6: 102.98798 | S6: 101.39261 | T6: 101.26182 | U6: 100.36344 | V6: 101.50183 | W6: 109.48476 | X6: 0
A7: Центральный федеральный округ | B7: 103.7 | C7: 106.05851 | D7: 108.82374 | E7: 105.12131 | F7: 97.521429 | G7: 100.53061 | H7: 98.124164 | I7: 101.20741 | J7: 100.83106 | K7: 116.19933 | L7: 111.14697 | M7: 118.33294 | N7: 102.29551 | O7: 102.36734 | P7: 102.22992 | Q7: 100.05169 | R7: 105.31715 | S7: 101.12368 | T7: 101.63 | U7: 100.29404 | V7: 100.77687 | W7: 119.58334 | X7: 0
A8: Белгородская область | B8: 102.5 | C8: 104.7 | D8: 113.2 | E8: 101.2 | F8: 90.1 | G8: 82 | H8: 88.3 | I8: 105.2 | J8: 104 | K8: 97.6 | L8: 98.3 | M8: 114.6 | N8: 96.8 | O8: 88.234112 | P8: 100.88925 | Q8: 92.9 | R8: 99.7 | S8: 102.7 | T8: 100.4 | U8: 98.9 | V8: 94.1 | W8: 106.3 | X8: 0
A9: Брянская область | B9: 103.2 | C9: 103.3 | D9: 103.2 | E9: 102.3 | F9: 103 | G9: 110.5 | H9: 106.4 | I9: 100 | J9: 102.8 | K9: 108.9 | L9: 102.3 | M9: 110.5 | N9: 101.3 | O9: 105.74469 | P9: 99.986932 | Q9: 101.6 | R9: 123.1 | S9: 102.2 | T9: 100.7 | U9: 99.9 | V9: 143.9 | W9: 99.5 | X9: 0
A10: Владимирская область | B10: 100.7 | C10: 101.7 | D10: 94.5 | E10: 103.5 | F10: 95.6 | G10: 106 | H10: 78.6 | I10: 103.2 | J10: 104.7 | K10: 94.6 | L10: 98.9 | M10: 108.5 | N10: 99.3 | O10: 94.529023 | P10: 101.95617 | Q10: 93.4 | R10: 104.1 | S10: 102.1 | T10: 99.9 | U10: 97.9 | V10: 109.4 | W10: 104.4 | X10: 0
A11: Воронежская область | B11: 103.1 | C11: 99.7 | D11: 89.3 | E11: 109.9 | F11: 87.3 | G11: 85.8 | H11: 83.8 | I11: 102.5 | J11: 111.9 | K11: 103 | L11: 119.7 | M11: 114.6 | N11: 109.5 | O11: 124.75277 | P11: 100.95234 | Q11: 111.2 | R11: 108.5 | S11: 102.2 | T11: 101.1 | U11: 99.3 | V11: 109.6 | W11: 89.9 | X11: 0
A12: Ивановская область | B12: 101.7 | C12: 118.8 | D12: 108 | E12: 101.8 | F12: 89 | G12: 118.4 | H12: 305.1 | I12: 94.9 | J12: 72 | K12: 87.8 | L12: 91.7 | M12: 112.3 | N12: 106.6 | O12: 116.28498 | P12: 101.17751 | Q12: 97.4 | R12: 107.5 | S12: 101.9 | T12: 100.1 | U12: 98.8 | V12: 104.9 | W12: 70.9 | X12: 0
A13: Калужская область | B13: 103 | C13: 101.8 | D13: 89.8 | E13: 107.7 | F13: 90.9 | G13: 85.1 | H13: 76.7 | I13: 100.7 | J13: 105.7 | K13: 104.1 | L13: 114.2 | M13: 114.8 | N13: 105.8 | O13: 114.39393 | P13: 101.78343 | Q13: 97.4 | R13: 103.3 | S13: 100.9 | T13: 97.8 | U13: 97.6 | V13: 108.1 | W13: 131.1 | X13: 0
A14: Костромская область | B14: 108.8 | C14: 104.7 | D14: 157.7 | E14: 97.5 | F14: 97.5 | G14: 112.6 | H14: 98.8 | I14: 100.1 | J14: 106.2 | K14: 97.2 | L14: 106.2 | M14: 257.1 | N14: 104.9 | O14: 108.77655 | P14: 102.57007 | Q14: 106.6 | R14: 118.5 | S14: 93.7 | T14: 100.4 | U14: 97.3 | V14: 90.9 | W14: 114.6 | X14: 0
A15: Курская область | B15: 103.1 | C15: 101.6 | D15: 110.9 | E15: 103.6 | F15: 89.4 | G15: 123.8 | H15: 122.7 | I15: 104.5 | J15: 104.6 | K15: 87.8 | L15: 103 | M15: 109.2 | N15: 100.6 | O15: 87.323208 | P15: 107.26275 | Q15: 86.5 | R15: 100.7 | S15: 101.2 | T15: 99.1 | U15: 101.9 | V15: 103.9 | W15: 99.9 | X15: 0
A16: Липецкая область | B16: 101.9 | C16: 106.1 | D16: 100.5 | E16: 105.9 | F16: 92.1 | G16: 107.9 | H16: 85.9 | I16: 100.7 | J16: 87.8 | K16: 147 | L16: 126.5 | M16: 95.8 | N16: 101.5 | O16: 98.958072 | P16: 102.66037 | Q16: 105.4 | R16: 84.6 | S16: 101.7 | T16: 98.5 | U16: 94.1 | V16: 98.8 | W16: 94 | X16: 0
A17: Московская область | B17: 102.3 | C17: 105.3 | D17: 70.5 | E17: 100.3 | F17: 104.8 | G17: 100 | H17: 123 | I17: 106.8 | J17: 97.7 | K17: 118.9 | L17: 114.8 | M17: 130.7 | N17: 102.4 | O17: 104.99042 | P17: 100.67812 | Q17: 86.9 | R17: 86.3 | S17: 94.6 | T17: 102.6 | U17: 99.6 | V17: 99.1 | W17: 108.2 | X17: 0
... A101: Чукотский автономный округ | B101: 103.6 | C101: 96.3 | D101: 97.2 | E101: 69.1 | F101: 100.9 | G101: 84 | H101: 151.4 | I101: 108.1 | J101: 92.1 | K101: 132.1 | L101: 129.9 | M101: 111.1 | N101: 140 | O101: 167.91742 | P101: 127.8117 | Q101: 533.9 | R101: 76.3 | S101: 101 | T101: 103.2 | U101: 99.3 | V101: 96.1 | W101: 109.6 | X101: 0
A103: 1) Данные динамического ряда, начиная с 2016 года, содержат изменения, связанные с внедрением международной методологии оценки жилищных услуг, производимых и потребляемых собственниками жилья; оценкой потребления основного капитала, исходя из его текущей рыночной стоимости.
A104: 2)Данные динамического ряда, начиная с 2017 года, содержат изменения, связанные с включением в формирование показателей деятельности: кредитных организаций; финансовых услуг, кроме услуг по страхованию и пенсионному обеспечению; негосударственных пенсионных фондов; вспомогательной в сфере финансовых услуг и страхования.

Sheet 1. 2019
A1: К содержанию
A2: Индексы физического объема валового регионального продукта и валовой добавленной стоимости по отраслям экономики в 2019 году1)2) (в процентах к предыдущему году)
B3: Валовой региональный продукт (валовая добавленная стоимость в основных ценах) | C3: Раздел A | D3: Раздел B | E3: Раздел C | F3: Раздел D | G3: Раздел E | H3: Раздел F | I3: Раздел G | J3: Раздел H | K3: Раздел I | L3: Раздел J | M3: Раздел K | N3: Раздел L | Q3: Раздел M | R3: Раздел N | S3: Раздел О | T3: Раздел P | U3: Раздел Q | V3: Раздел R | W3: Раздел S | X3: Раздел T
N4: Деятельность по операциям с недвижимым имуществом | O4: в том числе:
C5: Сельское, лесное хозяйство, охота, рыболовство и рыбоводство | D5: Добыча полезных ископаемых | E5: Обрабатывающие производства | F5: Обеспечение электрической энергией, газом и паром; кондиционирование воздуха | G5: Водоснабжение; водоотведение, организация сбора и утилизация отходов, деятельность по ликвидации загрязнений | H5: Строительство | I5: Торговля оптовая и розничная; ремонт автотранспортных средств и мотоциклов | J5: Транспортировка и хранение | K5: Деятельность гостиниц и предприятий общественного питания | L5: Деятельность в области информации и связи | M5: Деятельность финансовая и страховая | O5: Операции с недвижимым имуществом | P5: Услуги по проживанию в собственном жилище | Q5: Деятельность профессиональная, научная и техническая | R5: Деятельность административная и сопутствующие дополнительные услуги | S5: Государственное управление и обеспечение военной безопасности; социальное обеспечение | T5: Образование | U5: Деятельность в области здравоохранения и социальных услуг | V5: Деятельность в области культуры, спорта, организации досуга и развлечений | W5: Предоставление прочих видов услуг | X5: Деятельность домашних хозяйств как работодателей; недифференцированная деятельность частных домашних хозяйств по производству1)
A6: Российская Федерация из суммы субъектов | B6: 102 | C6: 103.89408 | D6: 103.56438 | E6: 101.44056 | F6: 100.51482 | G6: 96.942413 | H6: 102.20192 | I6: 100.15875 | J6: 102.40235 | K6: 101.51699 | L6: 107.37714 | M6: 108.91763 | N6: 99.898478 | O6: 96.216331 | P6: 102.43399 | Q6: 104.46265 | R6: 104.99055 | S6: 98.991556 | T6: 99.906017 | U6: 100.44377 | V6: 106.71036 | W6: 93.868686 | X6: 0
A7: Центральный федеральный округ | B7: 102.7 | C7: 105.91914 | D7: 103.1302 | E7: 101.77701 | F7: 102.86921 | G7: 91.632117 | H7: 116.20056 | I7: 99.942613 | J7: 103.1042 | K7: 97.625527 | L7: 107.33759 | M7: 111.33716 | N7: 96.853172 | O7: 90.367866 | P7: 102.85477 | Q7: 105.48165 | R7: 106.52833 | S7: 101.08625 | T7: 99.243887 | U7: 100.90993 | V7: 114.38283 | W7: 96.97756 | X7: 0
A8: Белгородская область | B8: 101.9 | C8: 102.3 | D8: 102.5 | E8: 98.2 | F8: 91.7 | G8: 129.8 | H8: 106.7 | I8: 103 | J8: 112.9 | K8: 103.4 | L8: 107.3 | M8: 96.3 | N8: 100.8 | O8: 104.84219 | P8: 99.240162 | Q8: 117 | R8: 94.8 | S8: 95 | T8: 102.8 | U8: 99.9 | V8: 102.9 | W8: 99.7 | X8: 0
A9: Брянская область | B9: 102.5 | C9: 106.8 | D9: 116.2 | E9: 100 | F9: 95.9 | G9: 83.7 | H9: 102.9 | I9: 104 | J9: 100.1 | K9: 108.9 | L9: 102.8 | M9: 107.4 | N9: 102.8 | O9: 107.21057 | P9: 101.36192 | Q9: 106.6 | R9: 94.8 | S9: 96.8 | T9: 99 | U9: 101.2 | V9: 122.2 | W9: 107.1 | X9: 0
A10: Владимирская область | B10: 106.3 | C10: 102.1 | D10: 107.2 | E10: 113 | F10: 106.1 | G10: 97.8 | H10: 108.6 | I10: 105.3 | J10: 107.7 | K10: 106.8 | L10: 94.5 | M10: 97.5 | N10: 109.1 | O10: 109.44235 | P10: 108.93779 | Q10: 93.5 | R10: 100.7 | S10: 99.5 | T10: 97.4 | U10: 98.2 | V10: 93.1 | W10: 99.1 | X10: 0
A11: Воронежская область | B11: 101.7 | C11: 102.1 | D11: 115.1 | E11: 100.4 | F11: 101.7 | G11: 117 | H11: 108.2 | I11: 98 | J11: 112 | K11: 108.9 | L11: 95.2 | M11: 112.2 | N11: 91.4 | O11: 76.137038 | P11: 102.0364 | Q11: 100.1 | R11: 126.7 | S11: 96.7 | T11: 99.8 | U11: 100 | V11: 100.6 | W11: 127.9 | X11: 0
A12: Ивановская область | B12: 102.6 | C12: 83.3 | D12: 117.6 | E12: 109 | F12: 111.7 | G12: 88.5 | H12: 106.4 | I12: 100.6 | J12: 97.1 | K12: 103.4 | L12: 100.8 | M12: 106.5 | N12: 100.7 | O12: 100.10967 | P12: 101.13554 | Q12: 144.3 | R12: 117.7 | S12: 94.6 | T12: 98.5 | U12: 97.5 | V12: 112.1 | W12: 84.5 | X12: 0
A13: Калужская область | B13: 102.1 | C13: 116.5 | D13: 99.8 | E13: 100.5 | F13: 106.8 | G13: 88.3 | H13: 112.1 | I13: 99.1 | J13: 106.4 | K13: 103.4 | L13: 95.5 | M13: 93.4 | N13: 99.6 | O13: 94.205538 | P13: 102.53675 | Q13: 112.3 | R13: 142.1 | S13: 98 | T13: 99.7 | U13: 101.3 | V13: 88.8 | W13: 82.4 | X13: 0
A14: Костромская область | B14: 99 | C14: 100 | D14: 101.2 | E14: 104.9 | F14: 116.4 | G14: 102.6 | H14: 101.6 | I14: 99.2 | J14: 108.9 | K14: 106.9 | L14: 97.3 | M14: 80.6 | N14: 92 | O14: 85.188668 | P14: 96.846295 | Q14: 98.1 | R14: 106.8 | S14: 97.5 | T14: 96.7 | U14: 102.4 | V14: 90.7 | W14: 73.6 | X14: 0
A15: Курская область | B15: 102.7 | C15: 103.6 | D15: 101.5 | E15: 106.2 | F15: 95.6 | G15: 92.9 | H15: 119.5 | I15: 102 | J15: 100 | K15: 103.5 | L15: 110.9 | M15: 99.8 | N15: 103.5 | O15: 110.35271 | P15: 101.03141 | Q15: 87 | R15: 94.8 | S15: 96.5 | T15: 99.7 | U15: 99.4 | V15: 98.1 | W15: 104.9 | X15: 0
A16: Липецкая область | B16: 98.3 | C16: 102.4 | D16: 108 | E16: 92.8 | F16: 102.3 | G16: 88.3 | H16: 110.4 | I16: 100.5 | J16: 105.5 | K16: 101 | L16: 104.2 | M16: 110.7 | N16: 101.9 | O16: 100.81336 | P16: 102.4428 | Q16: 100.2 | R16: 92.6 | S16: 97.1 | T16: 99.8 | U16: 100.2 | V16: 101.4 | W16: 107.2 | X16: 0
A17: Московская область | B17: 106.1 | C17: 109.3 | D17: 115.5 | E17: 105.4 | F17: 101.2 | G17: 92.4 | H17: 108 | I17: 105.6 | J17: 111.7 | K17: 105.5 | L17: 124.3 | M17: 105.2 | N17: 103.2 | O17: 97.116965 | P17: 106.63353 | Q17: 116.9 | R17: 126.8 | S17: 100.3 | T17: 105.5 | U17: 100.1 | V17: 104.9 | W17: 98.7 | X17: 0
... A101: Чукотский автономный округ | B101: 104.4 | C101: 158.5 | D101: 106.3 | E101: 137.7 | F101: 101.7 | G101: 103 | H101: 118.7 | I101: 108.1 | J101: 102.9 | K101: 180.2 | L101: 110.3 | M101: 87.1 | N101: 89.8 | O101: 71.378782 | P101: 102.81708 | Q101: 12 | R101: 535.4 | S101: 93.3 | T101: 99.4 | U101: 97.4 | V101: 80.8 | W101: 93.9 | X101: 0
A103: 1) Данные динамического ряда, начиная с 2016 года, содержат изменения, связанные с внедрением международной методологии оценки жилищных услуг, производимых и потребляемых собственниками жилья; оценкой потребления основного капитала, исходя из его текущей рыночной стоимости.
A104: 2)Данные динамического ряда, начиная с 2017 года, содержат изменения, связанные с включением в формирование показателей деятельности: кредитных организаций; финансовых услуг, кроме услуг по страхованию и пенсионному обеспечению; негосударственных пенсионных фондов; вспомогательной в сфере финансовых услуг и страхования.

Sheet 1. 2020
A1: К содержанию
A2: Индексы физического объема валового регионального продукта и валовой добавленной стоимости по отраслям экономики в 2020 году1)2) (в процентах к предыдущему году)
B3: Валовой региональный продукт (валовая добавленная стоимость в основных ценах) | C3: Раздел A | D3: Раздел B | E3: Раздел C | F3: Раздел D | G3: Раздел E | H3: Раздел F | I3: Раздел G | J3: Раздел H | K3: Раздел I | L3: Раздел J | M3: Раздел K | N3: Раздел L | Q3: Раздел M | R3: Раздел N | S3: Раздел О | T3: Раздел P | U3: Раздел Q | V3: Раздел R | W3: Раздел S | X3: Раздел T
N4: Деятельность по операциям с недвижимым имуществом | O4: в том числе:
C5: Сельское, лесное хозяйство, охота, рыболовство и рыбоводство | D5: Добыча полезных ископаемых | E5: Обрабатывающие производства | F5: Обеспечение электрической энергией, газом и паром; кондиционирование воздуха | G5: Водоснабжение; водоотведение, организация сбора и утилизация отходов, деятельность по ликвидации загрязнений | H5: Строительство | I5: Торговля оптовая и розничная; ремонт автотранспортных средств и мотоциклов | J5: Транспортировка и хранение | K5: Деятельность гостиниц и предприятий общественного питания | L5: Деятельность в области информации и связи | M5: Деятельность финансовая и страховая | O5: Операции с недвижимым имуществом | P5: Услуги по проживанию в собственном жилище | Q5: Деятельность профессиональная, научная и техническая | R5: Деятельность административная и сопутствующие дополнительные услуги | S5: Государственное управление и обеспечение военной безопасности; социальное обеспечение | T5: Образование | U5: Деятельность в области здравоохранения и социальных услуг | V5: Деятельность в области культуры, спорта, организации досуга и развлечений | W5: Предоставление прочих видов услуг | X5: Деятельность домашних хозяйств как работодателей; недифференцированная деятельность частных домашних хозяйств по производству1)
A6: Российская Федерация из суммы субъектов | B6: 98.3 | C6: 102.25896 | D6: 92.256918 | E6: 100.7704 | F6: 96.771483 | G6: 102.69222 | H6: 99.655349 | I6: 97.024225 | J6: 92.265472 | K6: 78.097426 | L6: 106.78589 | M6: 111.75848 | N6: 98.905002 | O6: 94.134304 | P6: 102.02418 | Q6: 102.44132 | R6: 94.251867 | S6: 101.5461 | T6: 98.104445 | U6: 99.773775 | V6: 82.766212 | W6: 88.841787 | X6: 0
A7: Центральный федеральный округ | B7: 100.3 | C7: 102.02497 | D7: 103.46307 | E7: 103.25858 | F7: 100.48744 | G7: 107.21845 | H7: 98.89188 | I7: 96.311334 | J7: 85.722739 | K7: 76.831158 | L7: 111.22385 | M7: 115.16825 | N7: 99.13421 | O7: 94.863904 | P7: 102.78329 | Q7: 104.23634 | R7: 90.274443 | S7: 103.50389 | T7: 98.759178 | U7: 101.46839 | V7: 84.090189 | W7: 93.514034 | X7: 0
A8: Белгородская область | B8: 100 | C8: 97.8 | D8: 104.8 | E8: 101.1 | F8: 99.8 | G8: 84.2 | H8: 103.5 | I8: 101.7 | J8: 82.3 | K8: 100.5 | L8: 110.5 | M8: 103.1 | N8: 102.3 | O8: 104.70784 | P8: 101.2543 | Q8: 92.3 | R8: 92.2 | S8: 94.8 | T8: 98.1 | U8: 98.4 | V8: 91 | W8: 98.6 | X8: 0
A9: Брянская область | B9: 99.5 | C9: 97.2 | D9: 86.5 | E9: 102.1 | F9: 96.5 | G9: 103.6 | H9: 126.9 | I9: 97.8 | J9: 96.3 | K9: 67 | L9: 102.2 | M9: 97.3 | N9: 100.3 | O9: 97.259116 | P9: 101.28322 | Q9: 92 | R9: 91.4 | S9: 99.6 | T9: 96.5 | U9: 101.4 | V9: 108.2 | W9: 87.9 | X9: 0
A10: Владимирская область | B10: 99.8 | C10: 100.3 | D10: 110.8 | E10: 105.9 | F10: 92.3 | G10: 107 | H10: 102.2 | I10: 93 | J10: 90.2 | K10: 82.8 | L10: 97.2 | M10: 110.9 | N10: 97.2 | O10: 91.480846 | P10: 100.382 | Q10: 102.1 | R10: 100.7 | S10: 99.7 | T10: 94.6 | U10: 98.6 | V10: 91.8 | W10: 90.9 | X10: 0
A11: Воронежская область | B11: 97.8 | C11: 100.5 | D11: 96.9 | E11: 108.9 | F11: 125.4 | G11: 112.5 | H11: 85.7 | I11: 94.6 | J11: 69.5 | K11: 83.9 | L11: 101.3 | M11: 108.3 | N11: 99 | O11: 85.373263 | P11: 105.6308 | Q11: 116.5 | R11: 91.7 | S11: 100.2 | T11: 96.4 | U11: 98.8 | V11: 76.3 | W11: 90.5 | X11: 0
A12: Ивановская область | B12: 101.3 | C12: 114.2 | D12: 98.1 | E12: 113.1 | F12: 104 | G12: 96.2 | H12: 101.4 | I12: 99.3 | J12: 82.1 | K12: 85.4 | L12: 93.8 | M12: 107.1 | N12: 100.9 | O12: 100.47882 | P12: 101.25292 | Q12: 95.5 | R12: 118.3 | S12: 100.4 | T12: 93.2 | U12: 99.6 | V12: 97.6 | W12: 74.3 | X12: 0
A13: Калужская область | B13: 98.7 | C13: 96.3 | D13: 106 | E13: 103.7 | F13: 101.4 | G13: 87.3 | H13: 88.3 | I13: 89.4 | J13: 99.5 | K13: 76.2 | L13: 89.1 | M13: 99.4 | N13: 98.9 | O13: 92.912448 | P13: 102.04522 | Q13: 104.5 | R13: 93 | S13: 99.5 | T13: 101.1 | U13: 97.1 | V13: 87.4 | W13: 96.7 | X13: 0
A14: Костромская область | B14: 93.7 | C14: 110 | D14: 129.6 | E14: 95.6 | F14: 81.4 | G14: 105.8 | H14: 105.2 | I14: 93.6 | J14: 94.9 | K14: 76.1 | L14: 105.3 | M14: 68.9 | N14: 96.7 | O14: 111.68031 | P14: 87.891168 | Q14: 104.3 | R14: 85.4 | S14: 99.3 | T14: 97.7 | U14: 96.2 | V14: 98.8 | W14: 94 | X14: 0
A15: Курская область | B15: 102.1 | C15: 111.3 | D15: 100.1 | E15: 107.2 | F15: 107.9 | G15: 77.5 | H15: 77.1 | I15: 98.1 | J15: 97.1 | K15: 77.2 | L15: 103.2 | M15: 106.6 | N15: 101.1 | O15: 98.22852 | P15: 102.1409 | Q15: 156.4 | R15: 99.6 | S15: 99.8 | T15: 99.6 | U15: 100.8 | V15: 91.6 | W15: 100.3 | X15: 0
A16: Липецкая область | B16: 102.7 | C16: 103.5 | D16: 113.7 | E16: 107 | F16: 92.5 | G16: 98.6 | H16: 104.1 | I16: 104.1 | J16: 96.9 | K16: 77.9 | L16: 101.9 | M16: 102.7 | N16: 98 | O16: 86.488331 | P16: 103.26025 | Q16: 91.8 | R16: 115.3 | S16: 97.2 | T16: 96.2 | U16: 100 | V16: 82.1 | W16: 84.3 | X16: 0
A17: Московская область | B17: 99 | C17: 83 | D17: 102.6 | E17: 108.5 | F17: 84.4 | G17: 112.4 | H17: 97.9 | I17: 101.2 | J17: 74.4 | K17: 82.9 | L17: 85 | M17: 117.3 | N17: 103.3 | O17: 94.309448 | P17: 108.34696 | Q17: 85.8 | R17: 92.6 | S17: 103.1 | T17: 99.8 | U17: 103.2 | V17: 102.6 | W17: 95.1 | X17: 0
... A101: Чукотский автономный округ | B101: 100.9 | C101: 82.5 | D101: 101.1 | E101: 73.3 | F101: 104.5 | G101: 79.1 | H101: 110.9 | I101: 102.2 | J101: 100.3 | K101: 139.8 | L101: 95 | M101: 85.1 | N101: 126.8 | O101: 186.55592 | P101: 97.729109 | Q101: 111.5 | R101: 35.7 | S101: 103.7 | T101: 99.3 | U101: 98.5 | V101: 93.4 | W101: 93.2 | X101: 0
A103: 1) Данные динамического ряда, начиная с 2016 года, содержат изменения, связанные с внедрением международной методологии оценки жилищных услуг, производимых и потребляемых собственниками жилья; оценкой потребления основного капитала, исходя из его текущей рыночной стоимости.
A104: 2)Данные динамического ряда, начиная с 2017 года, содержат изменения, связанные с включением в формирование показателей деятельности: кредитных организаций; финансовых услуг, кроме услуг по страхованию и пенсионному обеспечению; негосударственных пенсионных фондов; вспомогательной в сфере финансовых услуг и страхования.

Sheet 1. 2021
A1: К содержанию
A2: Индексы физического объема валового регионального продукта и валовой добавленной стоимости по отраслям экономики в 2021 году1)2) (в процентах к предыдущему году)
B3: Валовой региональный продукт (валовая добавленная стоимость в основных ценах) | C3: Раздел A | D3: Раздел B | E3: Раздел C | F3: Раздел D | G3: Раздел E | H3: Раздел F | I3: Раздел G | J3: Раздел H | K3: Раздел I | L3: Раздел J | M3: Раздел K | N3: Раздел L | Q3: Раздел M | R3: Раздел N | S3: Раздел О | T3: Раздел P | U3: Раздел Q | V3: Раздел R | W3: Раздел S | X3: Раздел T
N4: Деятельность по операциям с недвижимым имуществом | O4: в том числе:
C5: Сельское, лесное хозяйство, охота, рыболовство и рыбоводство | D5: Добыча полезных ископаемых | E5: Обрабатывающие производства | F5: Обеспечение электрической энергией, газом и паром; кондиционирование воздуха | G5: Водоснабжение; водоотведение, организация сбора и утилизация отходов, деятельность по ликвидации загрязнений | H5: Строительство | I5: Торговля оптовая и розничная; ремонт автотранспортных средств и мотоциклов | J5: Транспортировка и хранение | K5: Деятельность гостиниц и предприятий общественного питания | L5: Деятельность в области информации и связи | M5: Деятельность финансовая и страховая | O5: Операции с недвижимым имуществом | P5: Услуги по проживанию в собственном жилище | Q5: Деятельность профессиональная, научная и техническая | R5: Деятельность административная и сопутствующие дополнительные услуги | S5: Государственное управление и обеспечение военной безопасности; социальное обеспечение | T5: Образование | U5: Деятельность в области здравоохранения и социальных услуг | V5: Деятельность в области культуры, спорта, организации досуга и развлечений | W5: Предоставление прочих видов услуг | X5: Деятельность домашних хозяйств как работодателей; недифференцированная деятельность частных домашних хозяйств по производству1)
A6: Российская Федерация из суммы субъектов | B6: 107.2 | C6: 101.66487 | D6: 107.1226 | E6: 106.90004 | F6: 106.5046 | G6: 109.67453 | H6: 105.6725 | I6: 110.57317 | J6: 110.00931 | K6: 127.06972 | L6: 115.97024 | M6: 105.72511 | N6: 105.3874 | O6: 105.76066 | P6: 105.15163 | Q6: 107.75351 | R6: 114.63521 | S6: 100.01741 | T6: 101.89111 | U6: 102.82261 | V6: 120.8449 | W6: 108.46439 | X6: 0
A7: Центральный федеральный округ | B7: 109.3 | C7: 99.420727 | D7: 107.07873 | E7: 112.64506 | F7: 109.70044 | G7: 109.45606 | H7: 109.13274 | I7: 104.14975 | J7: 114.01435 | K7: 138.5269 | L7: 123.60661 | M7: 109.96235 | N7: 106.38002 | O7: 102.00604 | P7: 110.05037 | Q7: 109.01783 | R7: 127.20077 | S7: 100.76228 | T7: 103.82899 | U7: 103.46269 | V7: 134.13214 | W7: 105.05256 | X7: 0
A8: Белгородская область | B8: 102.7 | C8: 101.5 | D8: 107.8 | E8: 104.4 | F8: 103.6 | G8: 134.9 | H8: 91.6 | I8: 101.8 | J8: 105.1 | K8: 111.2 | L8: 93.4 | M8: 99.1 | N8: 98.3 | O8: 89.330881 | P8: 101.92478 | Q8: 103.6 | R8: 112.2 | S8: 99 | T8: 103.2 | U8: 100.8 | V8: 104.3 | W8: 105.1 | X8: 0
A9: Брянская область | B9: 103.7 | C9: 107.8 | D9: 117.8 | E9: 107.4 | F9: 116.4 | G9: 137.2 | H9: 77.8 | I9: 100.4 | J9: 103.3 | K9: 127.8 | L9: 104.2 | M9: 96.7 | N9: 99.9 | O9: 95.369612 | P9: 101.33502 | Q9: 124.1 | R9: 83.5 | S9: 98.9 | T9: 100.3 | U9: 100.1 | V9: 138.2 | W9: 102.9 | X9: 0
A10: Владимирская область | B10: 112.6 | C10: 98.9 | D10: 132.5 | E10: 129.2 | F10: 117.3 | G10: 105.6 | H10: 104.6 | I10: 109 | J10: 102.1 | K10: 125.8 | L10: 106.1 | M10: 94.4 | N10: 99.5 | O10: 96.697815 | P10: 100.83589 | Q10: 104.8 | R10: 111.1 | S10: 99.3 | T10: 99.8 | U10: 100.3 | V10: 117.1 | W10: 111.8 | X10: 0
A11: Воронежская область | B11: 104 | C11: 100.9 | D11: 109.1 | E11: 108.3 | F11: 100 | G11: 100.5 | H11: 91 | I11: 105.2 | J11: 103.5 | K11: 116.1 | L11: 107.6 | M11: 102.2 | N11: 113.1 | O11: 95.612689 | P11: 121.50653 | Q11: 102.2 | R11: 113.4 | S11: 99 | T11: 100.1 | U11: 103 | V11: 109 | W11: 107.6 | X11: 0
A12: Ивановская область | B12: 101.7 | C12: 84.3 | D12: 105.5 | E12: 103.8 | F12: 117.7 | G12: 97.6 | H12: 97 | I12: 101.8 | J12: 103.8 | K12: 99.9 | L12: 106.2 | M12: 90.2 | N12: 96.3 | O12: 87.588674 | P12: 102.32752 | Q12: 111.8 | R12: 137.2 | S12: 100.3 | T12: 98.9 | U12: 98.2 | V12: 105.6 | W12: 94.3 | X12: 0
A13: Калужская область | B13: 107.2 | C13: 99 | D13: 111.3 | E13: 113.7 | F13: 106.6 | G13: 129.5 | H13: 120.4 | I13: 105.9 | J13: 126.2 | K13: 123.8 | L13: 101.4 | M13: 93.7 | N13: 100.5 | O13: 96.960934 | P13: 102.32956 | Q13: 75.1 | R13: 99.9 | S13: 99.6 | T13: 100.6 | U13: 103 | V13: 130 | W13: 97.5 | X13: 0
A14: Костромская область | B14: 105.2 | C14: 96.9 | D14: 123.3 | E14: 107.8 | F14: 117.6 | G14: 96.2 | H14: 120.5 | I14: 103.2 | J14: 102.5 | K14: 115 | L14: 116.2 | M14: 106 | N14: 103.7 | O14: 99.933582 | P14: 106.32786 | Q14: 87.5 | R14: 105.5 | S14: 100 | T14: 101.1 | U14: 96.9 | V14: 113.8 | W14: 102.4 | X14: 0
A15: Курская область | B15: 105.8 | C15: 90.2 | D15: 103.7 | E15: 113.5 | F15: 97.7 | G15: 110.2 | H15: 141.1 | I15: 114.3 | J15: 103.4 | K15: 101.8 | L15: 96.8 | M15: 101.7 | N15: 97.8 | O15: 86.281475 | P15: 101.82501 | Q15: 182.8 | R15: 98.9 | S15: 98.7 | T15: 99.8 | U15: 101.5 | V15: 109.2 | W15: 97.8 | X15: 0
A16: Липецкая область | B16: 104.3 | C16: 86.2 | D16: 99.3 | E16: 112.4 | F16: 89 | G16: 128 | H16: 103.5 | I16: 100.8 | J16: 115.7 | K16: 116.9 | L16: 98.2 | M16: 94.3 | N16: 101.9 | O16: 97.313382 | P16: 103.62958 | Q16: 116.1 | R16: 114 | S16: 98.7 | T16: 103.6 | U16: 99.4 | V16: 123.6 | W16: 94.7 | X16: 0
A17: Московская область | B17: 111.3 | C17: 114.8 | D17: 106.4 | E17: 116.1 | F17: 111.1 | G17: 120.2 | H17: 104 | I17: 117.4 | J17: 109.4 | K17: 142.6 | L17: 104.1 | M17: 96 | N17: 111.1 | O17: 121.37455 | P17: 106.22192 | Q17: 109.8 | R17: 112.5 | S17: 102.3 | T17: 102.3 | U17: 101.7 | V17: 106.5 | W17: 126.1 | X17: 0
... A101: Чукотский автономный округ | B101: 106 | C101: 104.4 | D101: 102.1 | E101: 88 | F101: 104.6 | G101: 96.5 | H101: 140.6 | I101: 111.4 | J101: 114.5 | K101: 130.7 | L101: 91.7 | M101: 93.1 | N101: 106.2 | O101: 112.37193 | P101: 99.836892 | Q101: 185 | R101: 132.3 | S101: 100.3 | T101: 99 | U101: 99.8 | V101: 100.4 | W101: 96.5 | X101: 0
A103: 1) Данные динамического ряда, начиная с 2016 года, содержат изменения, связанные с внедрением международной методологии оценки жилищных услуг, производимых и потребляемых собственниками жилья; оценкой потребления основного капитала, исходя из его текущей рыночной стоимости.
A104: 2)Данные динамического ряда, начиная с 2017 года, содержат изменения, связанные с включением в формирование показателей деятельности: кредитных организаций; финансовых услуг, кроме услуг по страхованию и пенсионному обеспечению; негосударственных пенсионных фондов; вспомогательной в сфере финансовых услуг и страхования.

Sheet 1. 2022
A1: К содержанию
A2: Индексы физического объема валового регионального продукта и валовой добавленной стоимости по отраслям экономики в 2022 году1)2) (в процентах к предыдущему году)
B3: Валовой региональный продукт (валовая добавленная стоимость в основных ценах) | C3: Раздел A | D3: Раздел B | E3: Раздел C | F3: Раздел D | G3: Раздел E | H3: Раздел F | I3: Раздел G | J3: Раздел H | K3: Раздел I | L3: Раздел J | M3: Раздел K | N3: Раздел L | Q3: Раздел M | R3: Раздел N | S3: Раздел О | T3: Раздел P | U3: Раздел Q | V3: Раздел R | W3: Раздел S | X3: Раздел T
N4: Деятельность по операциям с недвижимым имуществом | O4: в том числе:
C5: Сельское, лесное хозяйство, охота, рыболовство и рыбоводство | D5: Добыча полезных ископаемых | E5: Обрабатывающие производства | F5: Обеспечение электрической энергией, газом и паром; кондиционирование воздуха | G5: Водоснабжение; водоотведение, организация сбора и утилизация отходов, деятельность по ликвидации загрязнений | H5: Строительство | I5: Торговля оптовая и розничная; ремонт автотранспортных средств и мотоциклов | J5: Транспортировка и хранение | K5: Деятельность гостиниц и предприятий общественного питания | L5: Деятельность в области информации и связи | M5: Деятельность финансовая и страховая | O5: Операции с недвижимым имуществом | P5: Услуги по проживанию в собственном жилище | Q5: Деятельность профессиональная, научная и техническая | R5: Деятельность административная и сопутствующие дополнительные услуги | S5: Государственное управление и обеспечение военной безопасности; социальное обеспечение | T5: Образование | U5: Деятельность в области здравоохранения и социальных услуг | V5: Деятельность в области культуры, спорта, организации досуга и развлечений | W5: Предоставление прочих видов услуг | X5: Деятельность домашних хозяйств как работодателей; недифференцированная деятельность частных домашних хозяйств по производству1)
A6: Российская Федерация из суммы субъектов | B6: 100.2 | C6: 106.59982 | D6: 99.513011 | E6: 99.787928 | F6: 100.05173 | G6: 96.553908 | H6: 108.09238 | I6: 93.660632 | J6: 101.68384 | K6: 104.76103 | L6: 102.52785 | M6: 96.010009 | N6: 102.14621 | O6: 101.83294 | P6: 102.31169 | Q6: 102.07668 | R6: 105.4846 | S6: 100.77231 | T6: 100.01326 | U6: 97.129998 | V6: 107.85604 | W6: 98.034981 | X6: 0
A7: Центральный федеральный округ | B7: 98.9 | C7: 104.35927 | D7: 90.494027 | E7: 99.486616 | F7: 98.917271 | G7: 95.713779 | H7: 104.9272 | I7: 88.716055 | J7: 100.94589 | K7: 101.44372 | L7: 101.10995 | M7: 97.422312 | N7: 101.85068 | O7: 97.411781 | P7: 104.59136 | Q7: 101.63341 | R7: 113.36497 | S7: 101.33143 | T7: 100.99183 | U7: 96.362185 | V7: 106.50164 | W7: 95.309299 | X7: 0
A8: Белгородская область | B8: 99.1 | C8: 100.2 | D8: 93.3 | E8: 109.2 | F8: 103.7 | G8: 94.6 | H8: 93.7 | I8: 96.1 | J8: 110.5 | K8: 109.8 | L8: 113.1 | M8: 95.6 | N8: 100.4 | O8: 115.04171 | P8: 96.232294 | Q8: 89.2 | R8: 103.1 | S8: 97.3 | T8: 100.3 | U8: 105 | V8: 103 | W8: 101.1 | X8: 0
A9: Брянская область | B9: 99.8 | C9: 100.4 | D9: 105.8 | E9: 111.9 | F9: 100.7 | G9: 80 | H9: 91.4 | I9: 93.2 | J9: 102.2 | K9: 104.7 | L9: 87.4 | M9: 95.4 | N9: 88.9 | O9: 92.15059 | P9: 87.701614 | Q9: 91.3 | R9: 116.2 | S9: 99.6 | T9: 99.2 | U9: 97.4 | V9: 119.4 | W9: 93.4 | X9: 0
A10: Владимирская область | B10: 93.3 | C10: 97 | D10: 122.1 | E10: 74.5 | F10: 99 | G10: 101.4 | H10: 177.4 | I10: 106.4 | J10: 104.6 | K10: 94.2 | L10: 112.6 | M10: 89.7 | N10: 104.3 | O10: 120.77167 | P10: 99.003211 | Q10: 125.7 | R10: 90.1 | S10: 98.4 | T10: 97.8 | U10: 98.9 | V10: 96.3 | W10: 92.1 | X10: 0
A11: Воронежская область | B11: 97.4 | C11: 112.4 | D11: 103.7 | E11: 84.8 | F11: 99 | G11: 96.8 | H11: 101 | I11: 87.8 | J11: 109.2 | K11: 101.1 | L11: 98.6 | M11: 89.9 | N11: 109.3 | O11: 102.33017 | P11: 111.87193 | Q11: 91.9 | R11: 90.6 | S11: 99.8 | T11: 98.7 | U11: 94.4 | V11: 109.2 | W11: 93.4 | X11: 0
A12: Ивановская область | B12: 99.7 | C12: 116.6 | D12: 85 | E12: 113.6 | F12: 85.9 | G12: 103 | H12: 78.6 | I12: 98.5 | J12: 102.5 | K12: 95.9 | L12: 94 | M12: 87.1 | N12: 93 | O12: 87.926926 | P12: 95.731017 | Q12: 94.5 | R12: 85.4 | S12: 99.4 | T12: 97.3 | U12: 96.4 | V12: 113.2 | W12: 108.9 | X12: 0
A13: Калужская область | B13: 88.5 | C13: 103.7 | D13: 79.6 | E13: 77.6 | F13: 99.9 | G13: 86.3 | H13: 88.7 | I13: 99 | J13: 117.1 | K13: 99 | L13: 84.8 | M13: 88.3 | N13: 94.9 | O13: 101.0442 | P13: 92.059571 | Q13: 69.8 | R13: 91 | S13: 99.2 | T13: 98.4 | U13: 99.4 | V13: 113.7 | W13: 101.6 | X13: 0
A14: Костромская область | B14: 99.2 | C14: 104.3 | D14: 108.8 | E14: 97.3 | F14: 104 | G14: 93 | H14: 70.5 | I14: 99.1 | J14: 100.2 | K14: 103.8 | L14: 106.9 | M14: 112.8 | N14: 101.7 | O14: 94.227769 | P14: 105.84402 | Q14: 106.5 | R14: 90.9 | S14: 96.4 | T14: 97.8 | U14: 99.2 | V14: 100.2 | W14: 109.1 | X14: 0
A15: Курская область | B15: 94.5 | C15: 111 | D15: 78.9 | E15: 107.2 | F15: 88.1 | G15: 87.6 | H15: 93 | I15: 94.8 | J15: 96.1 | K15: 104.6 | L15: 95.8 | M15: 84.9 | N15: 100.9 | O15: 100.95134 | P15: 100.90778 | Q15: 53.1 | R15: 99.4 | S15: 98.6 | T15: 98.8 | U15: 90 | V15: 121.3 | W15: 82.4 | X15: 0
A16: Липецкая область | B16: 91.9 | C16: 116 | D16: 93.8 | E16: 82.9 | F16: 99.5 | G16: 83.5 | H16: 81 | I16: 99 | J16: 102.4 | K16: 99.7 | L16: 104.4 | M16: 81.6 | N16: 101.1 | O16: 98.864027 | P16: 101.72652 | Q16: 98.8 | R16: 104.6 | S16: 100.1 | T16: 100.1 | U16: 99.3 | V16: 103.1 | W16: 96.4 | X16: 0
A17: Московская область | B17: 95 | C17: 103.2 | D17: 88.3 | E17: 99.1 | F17: 99.9 | G17: 97.7 | H17: 101.3 | I17: 84.6 | J17: 97.9 | K17: 99 | L17: 92 | M17: 87.7 | N17: 96.5 | O17: 101.99147 | P17: 94.012955 | Q17: 94.8 | R17: 90.5 | S17: 101.6 | T17: 98.6 | U17: 97.9 | V17: 108.7 | W17: 85.3 | X17: 0
... A101: Чукотский автономный округ | B101: 94.4 | C101: 89.2 | D101: 69.7 | E101: 130.4 | F101: 100.6 | G101: 89.9 | H101: 168 | I101: 96.3 | J101: 78.7 | K101: 167.1 | L101: 107.5 | M101: 91.9 | N101: 106.8 | O101: 90.114088 | P101: 126.86008 | Q101: 111 | R101: 93.9 | S101: 99.2 | T101: 99.3 | U101: 98.6 | V101: 105 | W101: 138.9 | X101: 0
A103: 1) Данные динамического ряда, начиная с 2016 года, содержат изменения, связанные с внедрением международной методологии оценки жилищных услуг, производимых и потребляемых собственниками жилья; оценкой потребления основного капитала, исходя из его текущей рыночной стоимости.
A104: 2)Данные динамического ряда, начиная с 2017 года, содержат изменения, связанные с включением в формирование показателей деятельности: кредитных организаций; финансовых услуг, кроме услуг по страхованию и пенсионному обеспечению; негосударственных пенсионных фондов; вспомогательной в сфере финансовых услуг и страхования.

Sheet 1. 2023
A1: К содержанию
A2: Индексы физического объема валового регионального продукта и валовой добавленной стоимости по отраслям экономики в 2023 году1)2) (в процентах к предыдущему году)
B3: Валовой региональный продукт (валовая добавленная стоимость в основных ценах) | C3: Раздел A | D3: Раздел B | E3: Раздел C | F3: Раздел D | G3: Раздел E | H3: Раздел F | I3: Раздел G | J3: Раздел H | K3: Раздел I | L3: Раздел J | M3: Раздел K | N3: Раздел L | Q3: Раздел M | R3: Раздел N | S3: Раздел О | T3: Раздел P | U3: Раздел Q | V3: Раздел R | W3: Раздел S | X3: Раздел T
N4: Деятельность по операциям с недвижимым имуществом | O4: в том числе:
C5: Сельское, лесное хозяйство, охота, рыболовство и рыбоводство | D5: Добыча полезных ископаемых | E5: Обрабатывающие производства | F5: Обеспечение электрической энергией, газом и паром; кондиционирование воздуха | G5: Водоснабжение; водоотведение, организация сбора и утилизация отходов, деятельность по ликвидации загрязнений | H5: Строительство | I5: Торговля оптовая и розничная; ремонт автотранспортных средств и мотоциклов | J5: Транспортировка и хранение | K5: Деятельность гостиниц и предприятий общественного питания | L5: Деятельность в области информации и связи | M5: Деятельность финансовая и страховая | O5: Операции с недвижимым имуществом | P5: Услуги по проживанию в собственном жилище | Q5: Деятельность профессиональная, научная и техническая | R5: Деятельность административная и сопутствующие дополнительные услуги | S5: Государственное управление и обеспечение военной безопасности; социальное обеспечение | T5: Образование | U5: Деятельность в области здравоохранения и социальных услуг | V5: Деятельность в области культуры, спорта, организации досуга и развлечений | W5: Предоставление прочих видов услуг | X5: Деятельность домашних хозяйств как работодателей; недифференцированная деятельность частных домашних хозяйств по производству1)
A6: Российская Федерация из суммы субъектов | B6: 105.2 | C6: 101.4738 | D6: 98.891663 | E6: 107.77514 | F6: 100.27564 | G6: 102.33781 | H6: 110.65446 | I6: 106.5874 | J6: 104.4192 | K6: 114.53431 | L6: 115.55356 | M6: 118.57459 | N6: 101.19269 | O6: 101.28118 | P6: 101.14802 | Q6: 110.53056 | R6: 109.24677 | S6: 100.40821 | T6: 100.13778 | U6: 100.98055 | V6: 106.3216 | W6: 112.55221 | X6: 0
A7: Центральный федеральный округ | B7: 108.4 | C7: 108.12687 | D7: 96.323078 | E7: 106.62342 | F7: 99.805398 | G7: 101.17571 | H7: 106.4619 | I7: 113.73095 | J7: 100.68434 | K7: 121.43161 | L7: 122.39941 | M7: 118.08856 | N7: 103.00396 | O7: 98.350181 | P7: 105.66673 | Q7: 110.91945 | R7: 106.51045 | S7: 101.70132 | T7: 101.39511 | U7: 101.86496 | V7: 104.35752 | W7: 119.20729 | X7: 0
A8: Белгородская область | B8: 103.2 | C8: 110.2 | D8: 94.4 | E8: 108.6 | F8: 100.9 | G8: 100.2 | H8: 110.9 | I8: 101 | J8: 116.2 | K8: 114.7 | L8: 108.4 | M8: 117 | N8: 93.9 | O8: 85.117413 | P8: 96.959049 | Q8: 115.1 | R8: 108.3 | S8: 101 | T8: 100.5 | U8: 99.3 | V8: 96.9 | W8: 103.5 | X8: 0
A9: Брянская область | B9: 106.2 | C9: 107.8 | D9: 58.4 | E9: 124.1 | F9: 98.4 | G9: 103.9 | H9: 122.8 | I9: 101.5 | J9: 105.6 | K9: 99.4 | L9: 110.3 | M9: 115.5 | N9: 110.7 | O9: 84.732857 | P9: 120.60965 | Q9: 129.5 | R9: 96.7 | S9: 96.4 | T9: 99.6 | U9: 105.1 | V9: 28.4 | W9: 118.4 | X9: 0
A10: Владимирская область | B10: 106.6 | C10: 116.7 | D10: 96.7 | E10: 106.6 | F10: 99.6 | G10: 93.3 | H10: 111.5 | I10: 112.5 | J10: 110.8 | K10: 103.6 | L10: 100 | M10: 109.5 | N10: 103.1 | O10: 95.022506 | P10: 105.9985 | Q10: 93.4 | R10: 134.1 | S10: 100.7 | T10: 98.7 | U10: 104.6 | V10: 107 | W10: 110.2 | X10: 0
A11: Воронежская область | B11: 103.7 | C11: 104.6 | D11: 105.8 | E11: 105.2 | F11: 104.6 | G11: 94.3 | H11: 108.8 | I11: 104.7 | J11: 100.4 | K11: 114.9 | L11: 89.4 | M11: 123.2 | N11: 90.9 | O11: 130.72882 | P11: 77.298738 | Q11: 109.1 | R11: 126.1 | S11: 101.3 | T11: 100 | U11: 104.7 | V11: 97.2 | W11: 123.8 | X11: 0
A12: Ивановская область | B12: 106.5 | C12: 128.8 | D12: 121.1 | E12: 108.7 | F12: 97.7 | G12: 102.8 | H12: 119.3 | I12: 113.3 | J12: 102 | K12: 100.8 | L12: 105.4 | M12: 114.3 | N12: 97.4 | O12: 112.22906 | P12: 91.647453 | Q12: 108.2 | R12: 123 | S12: 99.5 | T12: 97.7 | U12: 98.9 | V12: 106.7 | W12: 111.8 | X12: 0
A13: Калужская область | B13: 106.5 | C13: 107.9 | D13: 99.1 | E13: 113 | F13: 102.2 | G13: 96.9 | H13: 88 | I13: 109.7 | J13: 100.3 | K13: 123.6 | L13: 113.9 | M13: 118.9 | N13: 93.5 | O13: 85.984505 | P13: 96.754485 | Q13: 112.3 | R13: 122.2 | S13: 99.1 | T13: 100.8 | U13: 100.4 | V13: 107.9 | W13: 135.8 | X13: 0
A14: Костромская область | B14: 106.3 | C14: 118.4 | D14: 101.1 | E14: 107.6 | F14: 99.2 | G14: 101.6 | H14: 118.4 | I14: 99.2 | J14: 113.9 | K14: 128.9 | L14: 121.1 | M14: 113 | N14: 99.9 | O14: 81.757202 | P14: 107.95457 | Q14: 112.6 | R14: 118.6 | S14: 98.6 | T14: 98 | U14: 98.9 | V14: 105.6 | W14: 98.5 | X14: 0
A15: Курская область | B15: 105.4 | C15: 105.7 | D15: 93.4 | E15: 116.7 | F15: 104.1 | G15: 112.7 | H15: 105.8 | I15: 102.8 | J15: 103.9 | K15: 109.2 | L15: 118.3 | M15: 114.2 | N15: 101.1 | O15: 97.870877 | P15: 101.88382 | Q15: 135.9 | R15: 117 | S15: 98.9 | T15: 99 | U15: 97.6 | V15: 96.1 | W15: 105.3 | X15: 0
A16: Липецкая область | B16: 113.3 | C16: 107.6 | D16: 102.1 | E16: 131.1 | F16: 111 | G16: 148.1 | H16: 112.1 | I16: 103.3 | J16: 101.5 | K16: 107.4 | L16: 107.7 | M16: 104.5 | N16: 89.4 | O16: 89.5904 | P16: 89.306619 | Q16: 116.2 | R16: 109.1 | S16: 100.5 | T16: 98 | U16: 102.4 | V16: 109.9 | W16: 109.3 | X16: 0
A17: Московская область | B17: 109 | C17: 98.8 | D17: 129.1 | E17: 111.1 | F17: 97.3 | G17: 114.9 | H17: 100.1 | I17: 109.6 | J17: 111 | K17: 115.1 | L17: 129.3 | M17: 117.7 | N17: 108.6 | O17: 105.3377 | P17: 110.11827 | Q17: 133 | R17: 89.2 | S17: 101.7 | T17: 96.7 | U17: 100.5 | V17: 112.3 | W17: 117.7 | X17: 0
... A101: Чукотский автономный округ | B101: 111.7 | C101: 80.5 | D101: 128.1 | E101: 214 | F101: 103.8 | G101: 103.5 | H101: 120.4 | I101: 97.1 | J101: 94.1 | K101: 95 | L101: 104 | M101: 128.5 | N101: 89.6 | O101: 85.303427 | P101: 92.609252 | Q101: 110 | R101: 108.6 | S101: 101.3 | T101: 100.3 | U101: 97.5 | V101: 100.9 | W101: 97.7 | X101: 0
A103: 1) Данные динамического ряда, начиная с 2016 года, содержат изменения, связанные с внедрением международной методологии оценки жилищных услуг, производимых и потребляемых собственниками жилья; оценкой потребления основного капитала, исходя из его текущей рыночной стоимости.
A104: 2)Данные динамического ряда, начиная с 2017 года, содержат изменения, связанные с включением в формирование показателей деятельности: кредитных организаций; финансовых услуг, кроме услуг по страхованию и пенсионному обеспечению; негосударственных пенсионных фондов; вспомогательной в сфере финансовых услуг и страхования.

Sheet 1. 2024
A1: К содержанию
A2: Индексы физического объема валового регионального продукта и валовой добавленной стоимости по отраслям экономики в 2024 году1)2) (в процентах к предыдущему году)
B3: Валовой региональный продукт (валовая добавленная стоимость в основных ценах) | C3: Раздел A | D3: Раздел B | E3: Раздел C | F3: Раздел D | G3: Раздел E | H3: Раздел F | I3: Раздел G | J3: Раздел H | K3: Раздел I | L3: Раздел J | M3: Раздел K | N3: Раздел L | Q3: Раздел M | R3: Раздел N | S3: Раздел О | T3: Раздел P | U3: Раздел Q | V3: Раздел R | W3: Раздел S | X3: Раздел T
N4: Деятельность по операциям с недвижимым имуществом | O4: в том числе:
C5: Сельское, лесное хозяйство, охота, рыболовство и рыбоводство | D5: Добыча полезных ископаемых | E5: Обрабатывающие производства | F5: Обеспечение электрической энергией, газом и паром; кондиционирование воздуха | G5: Водоснабжение; водоотведение, организация сбора и утилизация отходов, деятельность по ликвидации загрязнений | H5: Строительство | I5: Торговля оптовая и розничная; ремонт автотранспортных средств и мотоциклов | J5: Транспортировка и хранение | K5: Деятельность гостиниц и предприятий общественного питания | L5: Деятельность в области информации и связи | M5: Деятельность финансовая и страховая | O5: Операции с недвижимым имуществом | P5: Услуги по проживанию в собственном жилище | Q5: Деятельность профессиональная, научная и техническая | R5: Деятельность административная и сопутствующие дополнительные услуги | S5: Государственное управление и обеспечение военной безопасности; социальное обеспечение | T5: Образование | U5: Деятельность в области здравоохранения и социальных услуг | V5: Деятельность в области культуры, спорта, организации досуга и развлечений | W5: Предоставление прочих видов услуг | X5: Деятельность домашних хозяйств как работодателей; недифференцированная деятельность частных домашних хозяйств по производству1)
A6: Российская Федерация из суммы субъектов | B6: 104.5 | C6: 98.550711 | D6: 100.32765 | E6: 106.3336 | F6: 102.88637 | G6: 102.118 | H6: 107.44966 | I6: 104.91886 | J6: 103.588 | K6: 117.55049 | L6: 112.65769 | M6: 107.38639 | N6: 104.55853 | O6: 106.48571 | P6: 103.5874 | Q6: 109.6648 | R6: 105.93577 | S6: 98.91402 | T6: 100.51013 | U6: 103.49467 | V6: 105.53493 | W6: 105.15501 | X6: 0
A7: Центральный федеральный округ | B7: 105.8 | C7: 95.674913 | D7: 101.09475 | E7: 105.99494 | F7: 102.59744 | G7: 102.16356 | H7: 97.413595 | I7: 105.80941 | J7: 103.2683 | K7: 122.03654 | L7: 115.03195 | M7: 109.29997 | N7: 104.75733 | O7: 108.08455 | P7: 102.85155 | Q7: 111.95452 | R7: 103.08363 | S7: 100.22811 | T7: 100.83201 | U7: 105.41282 | V7: 106.11059 | W7: 103.75751 | X7: 0
A8: Белгородская область | B8: 102.3 | C8: 93.8 | D8: 99.7 | E8: 103.4 | F8: 95.5 | G8: 99.8 | H8: 102.2 | I8: 107.4 | J8: 111.8 | K8: 107.8 | L8: 106.1 | M8: 139.2 | N8: 104 | O8: 101.27662 | P8: 104.85324 | Q8: 104.3 | R8: 104.4 | S8: 100.5 | T8: 98.9 | U8: 102.2 | V8: 102.1 | W8: 104.6 | X8: 0
A9: Брянская область | B9: 101 | C9: 96.1 | D9: 129.3 | E9: 107.5 | F9: 103.9 | G9: 89.4 | H9: 97.4 | I9: 102.4 | J9: 101.9 | K9: 106.2 | L9: 106.3 | M9: 92 | N9: 103.4 | O9: 128.3823 | P9: 97.360409 | Q9: 86.8 | R9: 107.9 | S9: 96.5 | T9: 101.1 | U9: 98.2 | V9: 76.4 | W9: 123.9 | X9: 0
A10: Владимирская область | B10: 99.3 | C10: 100.4 | D10: 99.6 | E10: 109.4 | F10: 103.8 | G10: 112.1 | H10: 53.9 | I10: 100.7 | J10: 98.4 | K10: 134.7 | L10: 96.8 | M10: 99 | N10: 93.9 | O10: 92.800106 | P10: 94.244488 | Q10: 92 | R10: 108.7 | S10: 98.8 | T10: 98.3 | U10: 102.3 | V10: 101.3 | W10: 96.4 | X10: 0
A11: Воронежская область | B11: 102 | C11: 87.8 | D11: 98.2 | E11: 106.1 | F11: 100.5 | G11: 100.6 | H11: 103.1 | I11: 106.5 | J11: 107.3 | K11: 114.7 | L11: 107.2 | M11: 103.3 | N11: 103.4 | O11: 98.081653 | P11: 106.15705 | Q11: 105.8 | R11: 111 | S11: 100.5 | T11: 97.2 | U11: 102.9 | V11: 102.5 | W11: 102.9 | X11: 0
A12: Ивановская область | B12: 100.9 | C12: 102.2 | D12: 98.4 | E12: 102 | F12: 96.9 | G12: 98.9 | H12: 116.2 | I12: 99.3 | J12: 121.3 | K12: 109.9 | L12: 106.7 | M12: 94.5 | N12: 89.6 | O12: 83.859887 | P12: 92.195368 | Q12: 103.4 | R12: 99.5 | S12: 98.3 | T12: 99.5 | U12: 101.6 | V12: 103.3 | W12: 107.7 | X12: 0
A13: Калужская область | B13: 106.6 | C13: 102.5 | D13: 107.6 | E13: 112.9 | F13: 110.4 | G13: 119 | H13: 119.1 | I13: 100 | J13: 98.4 | K13: 124 | L13: 94.7 | M13: 110.3 | N13: 100.2 | O13: 109.4933 | P13: 96.495753 | Q13: 94.9 | R13: 114.9 | S13: 105.5 | T13: 98.9 | U13: 98.7 | V13: 111 | W13: 117.8 | X13: 0
A14: Костромская область | B14: 103.2 | C14: 95.1 | D14: 113.2 | E14: 108 | F14: 101.1 | G14: 97.7 | H14: 98.3 | I14: 107.5 | J14: 103.5 | K14: 104.9 | L14: 94.9 | M14: 98.4 | N14: 102.5 | O14: 123.3204 | P14: 96.09567 | Q14: 132.4 | R14: 101.8 | S14: 97.5 | T14: 99.2 | U14: 99.3 | V14: 117.5 | W14: 99.9 | X14: 0
A15: Курская область | B15: 100 | C15: 87.5 | D15: 100.9 | E15: 108.4 | F15: 85.9 | G15: 99.4 | H15: 104 | I15: 102.6 | J15: 113.1 | K15: 118.3 | L15: 102.9 | M15: 101.6 | N15: 99.9 | O15: 107.53252 | P15: 98.082533 | Q15: 98.1 | R15: 96.2 | S15: 97.9 | T15: 97.7 | U15: 101.8 | V15: 90.5 | W15: 98.6 | X15: 0
A16: Липецкая область | B16: 101.7 | C16: 98.2 | D16: 99.6 | E16: 93.9 | F16: 95.9 | G16: 148.2 | H16: 126.6 | I16: 107.8 | J16: 114 | K16: 116 | L16: 105.6 | M16: 98.1 | N16: 106.4 | O16: 118.82205 | P16: 103.97866 | Q16: 111.9 | R16: 123.9 | S16: 98.2 | T16: 100.6 | U16: 109.5 | V16: 99 | W16: 101.6 | X16: 0
A17: Московская область | B17: 106.4 | C17: 94 | D17: 110.7 | E17: 109.9 | F17: 102.5 | G17: 111.1 | H17: 114.2 | I17: 110.1 | J17: 99.4 | K17: 118.5 | L17: 136 | M17: 98.6 | N17: 101.8 | O17: 107.86871 | P17: 98.741524 | Q17: 95.2 | R17: 115.4 | S17: 102.5 | T17: 104.7 | U17: 110.4 | V17: 90 | W17: 114.5 | X17: 0
... A101: Чукотский автономный округ | B101: 105.7 | C101: 81.7 | D101: 118.8 | E101: 110.8 | F101: 99.1 | G101: 120.3 | H101: 99.5 | I101: 104.3 | J101: 66.1 | K101: 135.1 | L101: 123.7 | M101: 107.6 | N101: 107 | O101: 113.8514 | P101: 102.45465 | Q101: 107.2 | R101: 109.3 | S101: 103 | T101: 97.9 | U101: 99.4 | V101: 103.1 | W101: 110.9 | X101: 0
A103: 1) Данные динамического ряда, начиная с 2016 года, содержат изменения, связанные с внедрением международной методологии оценки жилищных услуг, производимых и потребляемых собственниками жилья; оценкой потребления основного капитала, исходя из его текущей рыночной стоимости.
A104: 2)Данные динамического ряда, начиная с 2017 года, содержат изменения, связанные с включением в формирование показателей деятельности: кредитных организаций; финансовых услуг, кроме услуг по страхованию и пенсионному обеспечению; негосударственных пенсионных фондов; вспомогательной в сфере финансовых услуг и страхования.

Sheet 2.2016
A1: К содержанию
A2: Валовая добавленная стоимость по отраслям экономики в 2016 г.1)2) (в текущих ценах; тыс. руб.)
B3: Валовая добавленная стоимость | C3: в том числе
C4: Раздел A | D4: Раздел B | E4: Раздел C | F4: Раздел D | G4: Раздел E | H4: Раздел F | I4: Раздел G | J4: Раздел H | K4: Раздел I | L4: Раздел J | M4: Раздел K | N4: Раздел L | Q4: Раздел M | R4: Раздел N | S4: Раздел О | T4: Раздел P | U4: Раздел Q | V4: Раздел R | W4: Раздел S | X4: Раздел T
N5: Деятельность по операциям с недвижимым имуществом | O5: в том числе:
C6: Сельское, лесное хозяйство, охота, рыболовство и рыбоводство | D6: Добыча полезных ископаемых | E6: Обрабатывающие производства | F6: Обеспечение электрической энергией, газом и паром; кондиционирование воздуха | G6: Водоснабжение; водоотведение, организация сбора и утилизация отходов, деятельность по ликвидации загрязнений | H6: Строительство | I6: Торговля оптовая и розничная; ремонт автотранспортных средств и мотоциклов | J6: Транспортировка и хранение | K6: Деятельность гостиниц и предприятий общественного питания | L6: Деятельность в области информации и связи | M6: Деятельность финансовая и страховая | O6: Операции с недвижимым имуществом | P6: Услуги по проживанию в собственном жилище | Q6: Деятельность профессиональная, научная и техническая | R6: Деятельность административная и сопутствующие дополнительные услуги | S6: Государственное управление и обеспечение военной безопасности; социальное обеспечение | T6: Образование | U6: Деятельность в области здравоохранения и социальных услуг | V6: Деятельность в области культуры, спорта, организации досуга и развлечений | W6: Предоставление прочих видов услуг | X6: Деятельность домашних хозяйств как работодателей; недифференцированная деятельность частных домашних хозяйств по производству1)
A7: Российская Федерация из суммы субъектов Российской Федерации | B7: 7.4362795e+10 | C7: 3.4368721e+09 | D7: 7.5472801e+09 | E7: 1.1706463e+10 | F7: 2.457698e+09 | G7: 4.4799396e+08 | H7: 4.6259787e+09 | I7: 1.1704814e+10 | J7: 5.568533e+09 | K7: 7.3515615e+08 | L7: 2.1095646e+09 | M7: 6.0587258e+08 | N7: 8.0029072e+09 | O7: 3.0802511e+09 | P7: 4922656089 | Q7: 3.2427593e+09 | R7: 1.800926e+09 | S7: 4.5540086e+09 | T7: 2.1044747e+09 | U7: 2.7483382e+09 | V7: 6.0203627e+08 | W7: 3.6111825e+08 | X7: 0
A8: Центральный федеральный округ | B8: 2.6189814e+10 | C8: 7.7188549e+08 | D8: 1.3175264e+08 | E8: 3.8890467e+09 | F8: 9.0595384e+08 | G8: 1.3727882e+08 | H8: 1.3462023e+09 | I8: 6.0292245e+09 | J8: 1.6641753e+09 | K8: 2.1814893e+08 | L8: 1.1397394e+09 | M8: 4.4212424e+08 | N8: 3.5923081e+09 | O8: 1.5878347e+09 | P8: 2.0044734e+09 | Q8: 1.7958401e+09 | R8: 6.8611689e+08 | S8: 1.6100466e+09 | T8: 6.2849191e+08 | U8: 8.2940496e+08 | V8: 2.1314949e+08 | W8: 1.5892417e+08 | X8: 0
A9: Белгородская область | B9: 7.7824056e+08 | C9: 1.4101681e+08 | D9: 80102785 | E9: 1.5061163e+08 | F9: 19739503 | G9: 4701558.4 | H9: 50867786 | I9: 1.1098882e+08 | J9: 31899024 | K9: 3406082.1 | L9: 10789099 | M9: 1791641.9 | N9: 70297855 | O9: 20291390 | P9: 50006465 | Q9: 12171064 | R9: 9314575.8 | S9: 29571430 | T9: 18664258 | U9: 24461341 | V9: 4583206.1 | W9: 3262100.5 | X9: 0
A10: Брянская область | B10: 3.167637e+08 | C10: 51795284 | D10: 181425.84 | E10: 46814707 | F10: 9312851.6 | G10: 2154525.8 | H10: 14014918 | I10: 51733386 | J10: 23186964 | K10: 5363963.6 | L10: 6938853.1 | M10: 1205167.5 | N10: 41759421 | O10: 9695296 | P10: 32064124 | Q10: 5046317.8 | R10: 5425812.1 | S10: 24090068 | T10: 10646620 | U10: 12698497 | V10: 3122945.6 | W10: 1271972.6 | X10: 0
A11: Владимирская область | B11: 4.3162195e+08 | C11: 16597318 | D11: 1233536.5 | E11: 1.4256612e+08 | F11: 17002899 | G11: 4478370.9 | H11: 19382272 | I11: 48969570 | J11: 21923103 | K11: 3670065 | L11: 7760278.7 | M11: 1607881 | N11: 61797448 | O11: 22670620 | P11: 39126828 | Q11: 13929002 | R11: 7229187.6 | S11: 27168266 | T11: 11685475 | U11: 18789160 | V11: 3785085.5 | W11: 2046915.4 | X11: 0
